<?xml version="1.0" encoding="utf-8"?><testsuites><testsuite name="pytest" errors="1" failures="0" skipped="0" tests="1" time="10.130" timestamp="2025-08-05T16:58:26.962913+08:00" hostname="mayundebijibendiannao.local"><testcase classname="" name="testcase.test_2_site_add" time="0.000"><error message="collection failure">../../../Library/Python/3.13/lib/python/site-packages/pymysql/connections.py:649: in connect
    sock = socket.create_connection(
/opt/homebrew/Cellar/python@3.13/3.13.3/Frameworks/Python.framework/Versions/3.13/lib/python3.13/socket.py:864: in create_connection
    raise exceptions[0]
/opt/homebrew/Cellar/python@3.13/3.13.3/Frameworks/Python.framework/Versions/3.13/lib/python3.13/socket.py:849: in create_connection
    sock.connect(sa)
E   TimeoutError: timed out

During handling of the above exception, another exception occurred:
testcase/test_2_site_add.py:15: in &lt;module&gt;
    db = HandleMysql()
common/handle_sql.py:10: in __init__
    self.con = pymysql.connect(host=conf.get("mysql", "host"),
../../../Library/Python/3.13/lib/python/site-packages/pymysql/connections.py:361: in __init__
    self.connect()
../../../Library/Python/3.13/lib/python/site-packages/pymysql/connections.py:716: in connect
    raise exc
E   pymysql.err.OperationalError: (2003, "Can't connect to MySQL server on '10.60.17.2' (timed out)")</error></testcase></testsuite></testsuites>